<?xml version="1.0" ?>
<robot name="m2wr_description" xmlns:xacro="http://www.ros.org/wiki/xacro">

<xacro:include filename="$(find m2wr_description_description)/urdf/materials.xacro" />
<xacro:include filename="$(find m2wr_description_description)/urdf/m2wr_description.trans" />
<xacro:include filename="$(find m2wr_description_description)/urdf/m2wr_description.gazebo" />
<link name="base_link">
  <inertial>
    <origin rpy="0 0 0" xyz="-6.009357995619763e-17 -1.4235303499013823e-09 0.03360579876868525"/>
    <mass value="1.0339660627846412"/>
    <inertia ixx="0.000794" ixy="-0.0" ixz="-0.0" iyy="0.000826" iyz="-0.0" izz="0.001313"/>
  </inertial>
  <visual>
    <origin rpy="0 0 0" xyz="0 0 0"/>
    <geometry>
      <mesh filename="package://m2wr_description_description/meshes/base_link.stl" scale="0.001 0.001 0.001"/>
    </geometry>
    <material name="red"/>
  </visual>
  <collision>
    <origin rpy="0 0 0" xyz="0 0 0"/>
    <geometry>
      <mesh filename="package://m2wr_description_description/meshes/base_link.stl" scale="0.001 0.001 0.001"/>
    </geometry>
  </collision>
</link>

<link name="Component3_1">
  <inertial>
    <origin rpy="0 0 0" xyz="-4.9394705546698643e-17 -0.0019998049718631117 1.7202944714578283e-07"/>
    <mass value="0.1578336149163506"/>
    <inertia ixx="6.3e-05" ixy="0.0" ixz="-0.0" iyy="0.000126" iyz="0.0" izz="6.3e-05"/>
  </inertial>
  <visual>
    <origin rpy="0 0 0" xyz="0.0 0.060002 -0.040407"/>
    <geometry>
      <mesh filename="package://m2wr_description_description/meshes/Component3_1.stl" scale="0.001 0.001 0.001"/>
    </geometry>
    <material name="orange"/>
  </visual>
  <collision>
    <origin rpy="0 0 0" xyz="0.0 0.060002 -0.040407"/>
    <geometry>
      <mesh filename="package://m2wr_description_description/meshes/Component3_1.stl" scale="0.001 0.001 0.001"/>
    </geometry>
  </collision>
</link>

<link name="Component2_1">
  <inertial>
    <origin rpy="0 0 0" xyz="-3.427331697555865e-17 0.001999804971863098 1.7202944462002545e-07"/>
    <mass value="0.15783361491635134"/>
    <inertia ixx="6.3e-05" ixy="0.0" ixz="-0.0" iyy="0.000126" iyz="0.0" izz="6.3e-05"/>
  </inertial>
  <visual>
    <origin rpy="0 0 0" xyz="0.0 -0.060002 -0.040407"/>
    <geometry>
      <mesh filename="package://m2wr_description_description/meshes/Component2_1.stl" scale="0.001 0.001 0.001"/>
    </geometry>
    <material name="orange"/>
  </visual>
  <collision>
    <origin rpy="0 0 0" xyz="0.0 -0.060002 -0.040407"/>
    <geometry>
      <mesh filename="package://m2wr_description_description/meshes/Component2_1.stl" scale="0.001 0.001 0.001"/>
    </geometry>
  </collision>
</link>

<link name="Component4_1">
  <inertial>
    <origin rpy="0 0 0" xyz="-0.020000000000000046 2.220446049250313e-18 0.005999856949279396"/>
    <mass value="0.11304"/>
    <inertia ixx="3.5e-05" ixy="0.0" ixz="-0.0" iyy="5e-06" iyz="0.0" izz="3.8e-05"/>
  </inertial>
  <visual>
    <origin rpy="0 0 0" xyz="0.0 -0.0 -0.045005"/>
    <geometry>
      <mesh filename="package://m2wr_description_description/meshes/Component4_1.stl" scale="0.001 0.001 0.001"/>
    </geometry>
    <material name="blue"/>
  </visual>
  <collision>
    <origin rpy="0 0 0" xyz="0.0 -0.0 -0.045005"/>
    <geometry>
      <mesh filename="package://m2wr_description_description/meshes/Component4_1.stl" scale="0.001 0.001 0.001"/>
    </geometry>
   <surface>
      <friction>
        <ode>
          <mu>0</mu>
          <mu2>0</mu2>
          <slip1>1.0</slip1>
          <slip2>1.0</slip2>     
        </ode>
      </friction>
	</surface>
  </collision>
</link>

<joint name="Rev1" type="continuous">
  <origin rpy="0 0 0" xyz="0.0 -0.060002 0.040407"/>
  <parent link="base_link"/>
  <child link="Component3_1"/>
  <axis xyz="0.0 1.0 -0.0"/>
</joint>

<joint name="Rev2" type="continuous">
  <origin rpy="0 0 0" xyz="0.0 0.060002 0.040407"/>
  <parent link="base_link"/>
  <child link="Component2_1"/>
  <axis xyz="0.0 1.0 -0.0"/>
</joint>

<joint name="Rigid3" type="fixed">
  <origin rpy="0 0 0" xyz="0.0 0.0 0.045005"/>
  <parent link="base_link"/>
  <child link="Component4_1"/>
</joint>

</robot>
